Workbook
Name SegmentaciónDeDatos_Client: #N/A
Name SegmentaciónDeDatos_Client1: #N/A
Name SegmentaciónDeDatos_Client2: #N/A
Name SegmentaciónDeDatos_OOS__Clean: #N/A
Name SegmentaciónDeDatos_Status_Final: #N/A
Name SegmentaciónDeDatos_Status_Final__Clean: #N/A
Name SegmentaciónDeDatos_Week__Actual_Pull: #N/A

Sheet WEEKLY PULL-OUT SCHEDULE
A1: ℹ️ DEMO FILE — All data is fictitious for portfolio purposes only
A2: WEEKLY PULL-OUT SCHEDULE & TESTING STATUS — Demo Data
A4: Client | B4: Stability No. | C4: Product Name | D4: Timepoint | E4: Storage Conditions | F4: Scheduled Retrieval | G4: Window Start | H4: Window End | I4: Actual Pull Date | J4: Testing Deadline | K4: Days to Window | L4: STATUS | M4: Testing Status | N4: Status Final | O4: QIDR # | P4: OOS | Q4: Comment | R4: Documentation Completed | S4: KEY (Stability+Timepoint) | T4: Status Final (Clean) | U4: Year | V4: OOS (Clean) | W4: Week (Actual Pull)
A5: NovaMed Pharma | B5: 801 | C5: Omega-3 Fish Oil Capsules | D5: M9 | E5: 30°C/65%RH | F5: 45764 | G5: 45757 | H5: 45771 | I5: 45764 | J5: 45794 | K5: =IF(I5="","",I5-G5) -> 7 | L5: Active | M5: In Progress | N5: Completed | P5: N/A | R5: Yes | S5: =TRIM(CLEAN(B5))&"|"&TRIM(CLEAN(D5)) -> 801|M9 | T5: =IF(N5="","Pending",N5) -> Completed | U5: =IF(I5="","",YEAR(I5)) -> 2025 | V5: =IF(P5="N/A","No OOS",IF(ISNUMBER(FIND("OOS Closed",Q5)),"Closed","Open")) -> No OOS | W5: =IF(I5="", "", "Week " & INT((DAY(I5)-1)/7)+1 & " of " & TEXT(I5, "mmmm")) -> Week 3 of April
A6: NovaMed Pharma | B6: 801 | C6: Omega-3 Fish Oil Capsules | D6: M3 | E6: 40°C/75%RH | K6: =IF(I6="","",I6-G6) | P6: 26-03-007 | S6: =TRIM(CLEAN(B6))&"|"&TRIM(CLEAN(D6)) -> 801|M3 | T6: =IF(N6="","Pending",N6) -> Pending | U6: =IF(I6="","",YEAR(I6)) | V6: =IF(P6="N/A","No OOS",IF(ISNUMBER(FIND("OOS Closed",Q6)),"Closed","Open")) -> Open | W6: =IF(I6="", "", "Week " & INT((DAY(I6)-1)/7)+1 & " of " & TEXT(I6, "mmmm"))
A7: NovaMed Pharma | B7: 801 | C7: Omega-3 Fish Oil Capsules | D7: M24 | E7: 30°C/65%RH | K7: =IF(I7="","",I7-G7) | P7: 26-03-007 | S7: =TRIM(CLEAN(B7))&"|"&TRIM(CLEAN(D7)) -> 801|M24 | T7: =IF(N7="","Pending",N7) -> Pending | U7: =IF(I7="","",YEAR(I7)) | V7: =IF(P7="N/A","No OOS",IF(ISNUMBER(FIND("OOS Closed",Q7)),"Closed","Open")) -> Open | W7: =IF(I7="", "", "Week " & INT((DAY(I7)-1)/7)+1 & " of " & TEXT(I7, "mmmm"))
A8: NovaMed Pharma | B8: 801 | C8: Omega-3 Fish Oil Capsules | D8: M1 | E8: 40°C/75%RH | F8: 45799 | G8: 45793 | H8: 45807 | I8: 45800 | J8: 45830 | K8: =IF(I8="","",I8-G8) -> 7 | L8: Active | M8: In Progress | P8: N/A | S8: =TRIM(CLEAN(B8))&"|"&TRIM(CLEAN(D8)) -> 801|M1 | T8: =IF(N8="","Pending",N8) -> Pending | U8: =IF(I8="","",YEAR(I8)) -> 2025 | V8: =IF(P8="N/A","No OOS",IF(ISNUMBER(FIND("OOS Closed",Q8)),"Closed","Open")) -> No OOS | W8: =IF(I8="", "", "Week " & INT((DAY(I8)-1)/7)+1 & " of " & TEXT(I8, "mmmm")) -> Week 4 of May
A9: NovaMed Pharma | B9: 801 | C9: Omega-3 Fish Oil Capsules | D9: M12 | E9: 5°C±3°C | F9: 46161 | G9: 46154 | H9: 46168 | I9: 46161 | J9: 46191 | K9: =IF(I9="","",I9-G9) -> 7 | L9: Active | M9: In Progress | P9: N/A | S9: =TRIM(CLEAN(B9))&"|"&TRIM(CLEAN(D9)) -> 801|M12 | T9: =IF(N9="","Pending",N9) -> Pending | U9: =IF(I9="","",YEAR(I9)) -> 2026 | V9: =IF(P9="N/A","No OOS",IF(ISNUMBER(FIND("OOS Closed",Q9)),"Closed","Open")) -> No OOS | W9: =IF(I9="", "", "Week " & INT((DAY(I9)-1)/7)+1 & " of " & TEXT(I9, "mmmm")) -> Week 3 of May
A10: NovaMed Pharma | B10: 821 | C10: Zinc Lozenges 10mg | D10: M9 | E10: 5°C±3°C | F10: 45775 | G10: 45781 | H10: 45795 | I10: 45788 | J10: 45818 | K10: =IF(I10="","",I10-G10) -> 7 | L10: Active | M10: In Progress | N10: Not Completed | P10: N/A | S10: =TRIM(CLEAN(B10))&"|"&TRIM(CLEAN(D10)) -> 821|M9 | T10: =IF(N10="","Pending",N10) -> Not Completed | U10: =IF(I10="","",YEAR(I10)) -> 2025 | V10: =IF(P10="N/A","No OOS",IF(ISNUMBER(FIND("OOS Closed",Q10)),"Closed","Open")) -> No OOS | W10: =IF(I10="", "", "Week " & INT((DAY(I10)-1)/7)+1 & " of " & TEXT(I10, "mmmm")) -> Week 2 of May
A11: NovaMed Pharma | B11: 821 | C11: Zinc Lozenges 10mg | D11: M18 | E11: 40°C/75%RH | F11: 45932 | G11: 45927 | H11: 45941 | I11: 45934 | J11: 45964 | K11: =IF(I11="","",I11-G11) -> 7 | L11: Active | M11: In Progress | P11: 26-02-003 | S11: =TRIM(CLEAN(B11))&"|"&TRIM(CLEAN(D11)) -> 821|M18 | T11: =IF(N11="","Pending",N11) -> Pending | U11: =IF(I11="","",YEAR(I11)) -> 2025 | V11: =IF(P11="N/A","No OOS",IF(ISNUMBER(FIND("OOS Closed",Q11)),"Closed","Open")) -> Open | W11: =IF(I11="", "", "Week " & INT((DAY(I11)-1)/7)+1 & " of " & TEXT(I11, "mmmm")) -> Week 1 of October
A12: NovaMed Pharma | B12: 821 | C12: Zinc Lozenges 10mg | D12: M1 | E12: 30°C/65%RH | F12: 45775 | G12: 45777 | H12: 45791 | I12: 45784 | J12: 45814 | K12: =IF(I12="","",I12-G12) -> 7 | L12: Active | M12: In Progress | N12: Not Completed | P12: N/A | S12: =TRIM(CLEAN(B12))&"|"&TRIM(CLEAN(D12)) -> 821|M1 | T12: =IF(N12="","Pending",N12) -> Not Completed | U12: =IF(I12="","",YEAR(I12)) -> 2025 | V12: =IF(P12="N/A","No OOS",IF(ISNUMBER(FIND("OOS Closed",Q12)),"Closed","Open")) -> No OOS | W12: =IF(I12="", "", "Week " & INT((DAY(I12)-1)/7)+1 & " of " & TEXT(I12, "mmmm")) -> Week 1 of May
A13: NovaMed Pharma | B13: 821 | C13: Zinc Lozenges 10mg | D13: M24 | E13: 40°C/75%RH | F13: 46064 | G13: 46068 | H13: 46082 | I13: 46075 | J13: 46105 | K13: =IF(I13="","",I13-G13) -> 7 | L13: Active | M13: In Progress | P13: N/A | S13: =TRIM(CLEAN(B13))&"|"&TRIM(CLEAN(D13)) -> 821|M24 | T13: =IF(N13="","Pending",N13) -> Pending | U13: =IF(I13="","",YEAR(I13)) -> 2026 | V13: =IF(P13="N/A","No OOS",IF(ISNUMBER(FIND("OOS Closed",Q13)),"Closed","Open")) -> No OOS | W13: =IF(I13="", "", "Week " & INT((DAY(I13)-1)/7)+1 & " of " & TEXT(I13, "mmmm")) -> Week 4 of February
A14: NovaMed Pharma | B14: 821 | C14: Zinc Lozenges 10mg | D14: M3 | E14: 25°C/60%RH | F14: 45852 | G14: 45858 | H14: 45872 | I14: 45865 | J14: 45895 | K14: =IF(I14="","",I14-G14) -> 7 | L14: Active | M14: In Progress | N14: Completed | P14: 26-02-003 | R14: Yes | S14: =TRIM(CLEAN(B14))&"|"&TRIM(CLEAN(D14)) -> 821|M3 | T14: =IF(N14="","Pending",N14) -> Completed | U14: =IF(I14="","",YEAR(I14)) -> 2025 | V14: =IF(P14="N/A","No OOS",IF(ISNUMBER(FIND("OOS Closed",Q14)),"Closed","Open")) -> Open | W14: =IF(I14="", "", "Week " & INT((DAY(I14)-1)/7)+1 & " of " & TEXT(I14, "mmmm")) -> Week 4 of July
A15: NovaMed Pharma | B15: 832 | C15: Turmeric Extract Capsules | D15: M36 | E15: 40°C/75%RH | K15: =IF(I15="","",I15-G15) | P15: N/A | S15: =TRIM(CLEAN(B15))&"|"&TRIM(CLEAN(D15)) -> 832|M36 | T15: =IF(N15="","Pending",N15) -> Pending | U15: =IF(I15="","",YEAR(I15)) | V15: =IF(P15="N/A","No OOS",IF(ISNUMBER(FIND("OOS Closed",Q15)),"Closed","Open")) -> No OOS | W15: =IF(I15="", "", "Week " & INT((DAY(I15)-1)/7)+1 & " of " & TEXT(I15, "mmmm"))
A16: NovaMed Pharma | B16: 832 | C16: Turmeric Extract Capsules | D16: M9 | E16: 30°C/65%RH | F16: 46040 | G16: 46039 | H16: 46053 | I16: 46046 | J16: 46076 | K16: =IF(I16="","",I16-G16) -> 7 | L16: Active | M16: In Progress | P16: N/A | S16: =TRIM(CLEAN(B16))&"|"&TRIM(CLEAN(D16)) -> 832|M9 | T16: =IF(N16="","Pending",N16) -> Pending | U16: =IF(I16="","",YEAR(I16)) -> 2026 | V16: =IF(P16="N/A","No OOS",IF(ISNUMBER(FIND("OOS Closed",Q16)),"Closed","Open")) -> No OOS | W16: =IF(I16="", "", "Week " & INT((DAY(I16)-1)/7)+1 & " of " & TEXT(I16, "mmmm")) -> Week 4 of January
A17: NovaMed Pharma | B17: 832 | C17: Turmeric Extract Capsules | D17: M18 | E17: 30°C/65%RH | K17: =IF(I17="","",I17-G17) | P17: N/A | R17: Yes | S17: =TRIM(CLEAN(B17))&"|"&TRIM(CLEAN(D17)) -> 832|M18 | T17: =IF(N17="","Pending",N17) -> Pending | U17: =IF(I17="","",YEAR(I17)) | V17: =IF(P17="N/A","No OOS",IF(ISNUMBER(FIND("OOS Closed",Q17)),"Closed","Open")) -> No OOS | W17: =IF(I17="", "", "Week " & INT((DAY(I17)-1)/7)+1 & " of " & TEXT(I17, "mmmm"))
A18: NovaMed Pharma | B18: 832 | C18: Turmeric Extract Capsules | D18: M24 | E18: 5°C±3°C | F18: 45955 | G18: 45957 | H18: 45971 | I18: 45964 | J18: 45994 | K18: =IF(I18="","",I18-G18) -> 7 | L18: Active | M18: In Progress | N18: Completed | P18: 26-03-007 | R18: Yes | S18: =TRIM(CLEAN(B18))&"|"&TRIM(CLEAN(D18)) -> 832|M24 | T18: =IF(N18="","Pending",N18) -> Completed | U18: =IF(I18="","",YEAR(I18)) -> 2025 | V18: =IF(P18="N/A","No OOS",IF(ISNUMBER(FIND("OOS Closed",Q18)),"Closed","Open")) -> Open | W18: =IF(I18="", "", "Week " & INT((DAY(I18)-1)/7)+1 & " of " & TEXT(I18, "mmmm")) -> Week 1 of November
A19: NovaMed Pharma | B19: 833 | C19: CoQ10 100mg Softgels | D19: M12 | E19: 40°C/75%RH | F19: 45892 | G19: 45891 | H19: 45905 | I19: 45898 | J19: 45928 | K19: =IF(I19="","",I19-G19) -> 7 | L19: Active | M19: In Progress | N19: Not Completed | O19: QIDR-880 | P19: 26-04-012 | S19: =TRIM(CLEAN(B19))&"|"&TRIM(CLEAN(D19)) -> 833|M12 | T19: =IF(N19="","Pending",N19) -> Not Completed | U19: =IF(I19="","",YEAR(I19)) -> 2025 | V19: =IF(P19="N/A","No OOS",IF(ISNUMBER(FIND("OOS Closed",Q19)),"Closed","Open")) -> Open | W19: =IF(I19="", "", "Week " & INT((DAY(I19)-1)/7)+1 & " of " & TEXT(I19, "mmmm")) -> Week 5 of August
A20: NovaMed Pharma | B20: 833 | C20: CoQ10 100mg Softgels | D20: M24 | E20: 30°C/65%RH | F20: 45789 | G20: 45795 | H20: 45809 | I20: 45802 | J20: 45832 | K20: =IF(I20="","",I20-G20) -> 7 | L20: Active | M20: In Progress | P20: N/A | S20: =TRIM(CLEAN(B20))&"|"&TRIM(CLEAN(D20)) -> 833|M24 | T20: =IF(N20="","Pending",N20) -> Pending | U20: =IF(I20="","",YEAR(I20)) -> 2025 | V20: =IF(P20="N/A","No OOS",IF(ISNUMBER(FIND("OOS Closed",Q20)),"Closed","Open")) -> No OOS | W20: =IF(I20="", "", "Week " & INT((DAY(I20)-1)/7)+1 & " of " & TEXT(I20, "mmmm")) -> Week 4 of May
A21: NovaMed Pharma | B21: 833 | C21: CoQ10 100mg Softgels | D21: M18 | E21: 40°C/75%RH | F21: 46132 | G21: 46139 | H21: 46153 | I21: 46146 | J21: 46176 | K21: =IF(I21="","",I21-G21) -> 7 | L21: Active | M21: In Progress | P21: N/A | S21: =TRIM(CLEAN(B21))&"|"&TRIM(CLEAN(D21)) -> 833|M18 | T21: =IF(N21="","Pending",N21) -> Pending | U21: =IF(I21="","",YEAR(I21)) -> 2026 | V21: =IF(P21="N/A","No OOS",IF(ISNUMBER(FIND("OOS Closed",Q21)),"Closed","Open")) -> No OOS | W21: =IF(I21="", "", "Week " & INT((DAY(I21)-1)/7)+1 & " of " & TEXT(I21, "mmmm")) -> Week 1 of May
A22: BioCore Labs | B22: 843 | C22: Iron Supplement Drops | D22: M1 | E22: 30°C/65%RH | K22: =IF(I22="","",I22-G22) | P22: N/A | S22: =TRIM(CLEAN(B22))&"|"&TRIM(CLEAN(D22)) -> 843|M1 | T22: =IF(N22="","Pending",N22) -> Pending | U22: =IF(I22="","",YEAR(I22)) | V22: =IF(P22="N/A","No OOS",IF(ISNUMBER(FIND("OOS Closed",Q22)),"Closed","Open")) -> No OOS | W22: =IF(I22="", "", "Week " & INT((DAY(I22)-1)/7)+1 & " of " & TEXT(I22, "mmmm"))
A23: BioCore Labs | B23: 843 | C23: Iron Supplement Drops | D23: M3 | E23: 30°C/65%RH | F23: 46027 | G23: 46022 | H23: 46036 | I23: 46029 | J23: 46059 | K23: =IF(I23="","",I23-G23) -> 7 | L23: Active | M23: In Progress | P23: 26-03-007 | Q23: OOS Closed | S23: =TRIM(CLEAN(B23))&"|"&TRIM(CLEAN(D23)) -> 843|M3 | T23: =IF(N23="","Pending",N23) -> Pending | U23: =IF(I23="","",YEAR(I23)) -> 2026 | V23: =IF(P23="N/A","No OOS",IF(ISNUMBER(FIND("OOS Closed",Q23)),"Closed","Open")) -> Closed | W23: =IF(I23="", "", "Week " & INT((DAY(I23)-1)/7)+1 & " of " & TEXT(I23, "mmmm")) -> Week 1 of January
A24: BioCore Labs | B24: 843 | C24: Iron Supplement Drops | D24: M12 | E24: 5°C±3°C | F24: 46081 | G24: 46084 | H24: 46098 | I24: 46091 | J24: 46121 | K24: =IF(I24="","",I24-G24) -> 7 | L24: Active | M24: In Progress | P24: 26-04-012 | Q24: OOS Closed | S24: =TRIM(CLEAN(B24))&"|"&TRIM(CLEAN(D24)) -> 843|M12 | T24: =IF(N24="","Pending",N24) -> Pending | U24: =IF(I24="","",YEAR(I24)) -> 2026 | V24: =IF(P24="N/A","No OOS",IF(ISNUMBER(FIND("OOS Closed",Q24)),"Closed","Open")) -> Closed | W24: =IF(I24="", "", "Week " & INT((DAY(I24)-1)/7)+1 & " of " & TEXT(I24, "mmmm")) -> Week 2 of March
A25: BioCore Labs | B25: 843 | C25: Iron Supplement Drops | D25: M36 | E25: 30°C/65%RH | F25: 45921 | G25: 45914 | H25: 45928 | I25: 45921 | J25: 45951 | K25: =IF(I25="","",I25-G25) -> 7 | L25: Active | M25: In Progress | P25: N/A | S25: =TRIM(CLEAN(B25))&"|"&TRIM(CLEAN(D25)) -> 843|M36 | T25: =IF(N25="","Pending",N25) -> Pending | U25: =IF(I25="","",YEAR(I25)) -> 2025 | V25: =IF(P25="N/A","No OOS",IF(ISNUMBER(FIND("OOS Closed",Q25)),"Closed","Open")) -> No OOS | W25: =IF(I25="", "", "Week " & INT((DAY(I25)-1)/7)+1 & " of " & TEXT(I25, "mmmm")) -> Week 3 of September
A26: BioCore Labs | B26: 851 | C26: Vitamin C 500mg Tablets | D26: M1 | E26: 30°C/65%RH | K26: =IF(I26="","",I26-G26) | P26: 26-01-001 | Q26: OOS Closed | S26: =TRIM(CLEAN(B26))&"|"&TRIM(CLEAN(D26)) -> 851|M1 | T26: =IF(N26="","Pending",N26) -> Pending | U26: =IF(I26="","",YEAR(I26)) | V26: =IF(P26="N/A","No OOS",IF(ISNUMBER(FIND("OOS Closed",Q26)),"Closed","Open")) -> Closed | W26: =IF(I26="", "", "Week " & INT((DAY(I26)-1)/7)+1 & " of " & TEXT(I26, "mmmm"))
A27: BioCore Labs | B27: 851 | C27: Vitamin C 500mg Tablets | D27: M24 | E27: 5°C±3°C | F27: 46190 | G27: 46192 | H27: 46206 | I27: 46199 | J27: 46229 | K27: =IF(I27="","",I27-G27) -> 7 | L27: Active | M27: In Progress | P27: 26-04-012 | S27: =TRIM(CLEAN(B27))&"|"&TRIM(CLEAN(D27)) -> 851|M24 | T27: =IF(N27="","Pending",N27) -> Pending | U27: =IF(I27="","",YEAR(I27)) -> 2026 | V27: =IF(P27="N/A","No OOS",IF(ISNUMBER(FIND("OOS Closed",Q27)),"Closed","Open")) -> Open | W27: =IF(I27="", "", "Week " & INT((DAY(I27)-1)/7)+1 & " of " & TEXT(I27, "mmmm")) -> Week 4 of June
A28: BioCore Labs | B28: 851 | C28: Vitamin C 500mg Tablets | D28: M6 | E28: 5°C±3°C | F28: 45787 | G28: 45790 | H28: 45804 | I28: 45797 | J28: 45827 | K28: =IF(I28="","",I28-G28) -> 7 | L28: Active | M28: In Progress | O28: QIDR-155 | P28: 26-02-003 | S28: =TRIM(CLEAN(B28))&"|"&TRIM(CLEAN(D28)) -> 851|M6 | T28: =IF(N28="","Pending",N28) -> Pending | U28: =IF(I28="","",YEAR(I28)) -> 2025 | V28: =IF(P28="N/A","No OOS",IF(ISNUMBER(FIND("OOS Closed",Q28)),"Closed","Open")) -> Open | W28: =IF(I28="", "", "Week " & INT((DAY(I28)-1)/7)+1 & " of " & TEXT(I28, "mmmm")) -> Week 3 of May
A29: HealthSync Ltd | B29: 853 | C29: Omega-3 Fish Oil Capsules | D29: M18 | E29: 25°C/60%RH | F29: 45813 | G29: 45812 | H29: 45826 | I29: 45819 | J29: 45849 | K29: =IF(I29="","",I29-G29) -> 7 | L29: Active | M29: In Progress | N29: Not Completed | P29: 26-01-001 | S29: =TRIM(CLEAN(B29))&"|"&TRIM(CLEAN(D29)) -> 853|M18 | T29: =IF(N29="","Pending",N29) -> Not Completed | U29: =IF(I29="","",YEAR(I29)) -> 2025 | V29: =IF(P29="N/A","No OOS",IF(ISNUMBER(FIND("OOS Closed",Q29)),"Closed","Open")) -> Open | W29: =IF(I29="", "", "Week " & INT((DAY(I29)-1)/7)+1 & " of " & TEXT(I29, "mmmm")) -> Week 2 of June
A30: HealthSync Ltd | B30: 853 | C30: Omega-3 Fish Oil Capsules | D30: M24 | E30: 25°C/60%RH | F30: 46028 | G30: 46022 | H30: 46036 | I30: 46029 | J30: 46059 | K30: =IF(I30="","",I30-G30) -> 7 | L30: Active | M30: In Progress | N30: Completed | O30: QIDR-969 | P30: N/A | R30: Yes | S30: =TRIM(CLEAN(B30))&"|"&TRIM(CLEAN(D30)) -> 853|M24 | T30: =IF(N30="","Pending",N30) -> Completed | U30: =IF(I30="","",YEAR(I30)) -> 2026 | V30: =IF(P30="N/A","No OOS",IF(ISNUMBER(FIND("OOS Closed",Q30)),"Closed","Open")) -> No OOS | W30: =IF(I30="", "", "Week " & INT((DAY(I30)-1)/7)+1 & " of " & TEXT(I30, "mmmm")) -> Week 1 of January
A31: HealthSync Ltd | B31: 853 | C31: Omega-3 Fish Oil Capsules | D31: M1 | E31: 5°C±3°C | F31: 45949 | G31: 45949 | H31: 45963 | I31: 45956 | J31: 45986 | K31: =IF(I31="","",I31-G31) -> 7 | L31: Active | M31: In Progress | O31: QIDR-268 | P31: N/A | S31: =TRIM(CLEAN(B31))&"|"&TRIM(CLEAN(D31)) -> 853|M1 | T31: =IF(N31="","Pending",N31) -> Pending | U31: =IF(I31="","",YEAR(I31)) -> 2025 | V31: =IF(P31="N/A","No OOS",IF(ISNUMBER(FIND("OOS Closed",Q31)),"Closed","Open")) -> No OOS | W31: =IF(I31="", "", "Week " & INT((DAY(I31)-1)/7)+1 & " of " & TEXT(I31, "mmmm")) -> Week 4 of October
A32: HealthSync Ltd | B32: 853 | C32: Omega-3 Fish Oil Capsules | D32: M3 | E32: 5°C±3°C | F32: 45943 | G32: 45940 | H32: 45954 | I32: 45947 | J32: 45977 | K32: =IF(I32="","",I32-G32) -> 7 | L32: Active | M32: In Progress | P32: 26-01-001 | S32: =TRIM(CLEAN(B32))&"|"&TRIM(CLEAN(D32)) -> 853|M3 | T32: =IF(N32="","Pending",N32) -> Pending | U32: =IF(I32="","",YEAR(I32)) -> 2025 | V32: =IF(P32="N/A","No OOS",IF(ISNUMBER(FIND("OOS Closed",Q32)),"Closed","Open")) -> Open | W32: =IF(I32="", "", "Week " & INT((DAY(I32)-1)/7)+1 & " of " & TEXT(I32, "mmmm")) -> Week 3 of October
A33: HealthSync Ltd | B33: 853 | C33: Omega-3 Fish Oil Capsules | D33: M12 | E33: 40°C/75%RH | F33: 45768 | G33: 45770 | H33: 45784 | I33: 45777 | J33: 45807 | K33: =IF(I33="","",I33-G33) -> 7 | L33: Active | M33: In Progress | P33: N/A | S33: =TRIM(CLEAN(B33))&"|"&TRIM(CLEAN(D33)) -> 853|M12 | T33: =IF(N33="","Pending",N33) -> Pending | U33: =IF(I33="","",YEAR(I33)) -> 2025 | V33: =IF(P33="N/A","No OOS",IF(ISNUMBER(FIND("OOS Closed",Q33)),"Closed","Open")) -> No OOS | W33: =IF(I33="", "", "Week " & INT((DAY(I33)-1)/7)+1 & " of " & TEXT(I33, "mmmm")) -> Week 5 of April
A34: HealthSync Ltd | B34: 853 | C34: Omega-3 Fish Oil Capsules | D34: M36 | E34: 25°C/60%RH | F34: 45991 | G34: 45998 | H34: 46012 | I34: 46005 | J34: 46035 | K34: =IF(I34="","",I34-G34) -> 7 | L34: Active | M34: In Progress | O34: QIDR-182 | P34: N/A | S34: =TRIM(CLEAN(B34))&"|"&TRIM(CLEAN(D34)) -> 853|M36 | T34: =IF(N34="","Pending",N34) -> Pending | U34: =IF(I34="","",YEAR(I34)) -> 2025 | V34: =IF(P34="N/A","No OOS",IF(ISNUMBER(FIND("OOS Closed",Q34)),"Closed","Open")) -> No OOS | W34: =IF(I34="", "", "Week " & INT((DAY(I34)-1)/7)+1 & " of " & TEXT(I34, "mmmm")) -> Week 2 of December
A35: HealthSync Ltd | B35: 856 | C35: Probiotic Complex | D35: M9 | E35: 25°C/60%RH | F35: 46036 | G35: 46032 | H35: 46046 | I35: 46039 | J35: 46069 | K35: =IF(I35="","",I35-G35) -> 7 | L35: Active | M35: In Progress | P35: N/A | S35: =TRIM(CLEAN(B35))&"|"&TRIM(CLEAN(D35)) -> 856|M9 | T35: =IF(N35="","Pending",N35) -> Pending | U35: =IF(I35="","",YEAR(I35)) -> 2026 | V35: =IF(P35="N/A","No OOS",IF(ISNUMBER(FIND("OOS Closed",Q35)),"Closed","Open")) -> No OOS | W35: =IF(I35="", "", "Week " & INT((DAY(I35)-1)/7)+1 & " of " & TEXT(I35, "mmmm")) -> Week 3 of January
A36: HealthSync Ltd | B36: 856 | C36: Probiotic Complex | D36: M36 | E36: 40°C/75%RH | F36: 46010 | G36: 46008 | H36: 46022 | I36: 46015 | J36: 46045 | K36: =IF(I36="","",I36-G36) -> 7 | L36: Active | M36: In Progress | P36: N/A | S36: =TRIM(CLEAN(B36))&"|"&TRIM(CLEAN(D36)) -> 856|M36 | T36: =IF(N36="","Pending",N36) -> Pending | U36: =IF(I36="","",YEAR(I36)) -> 2025 | V36: =IF(P36="N/A","No OOS",IF(ISNUMBER(FIND("OOS Closed",Q36)),"Closed","Open")) -> No OOS | W36: =IF(I36="", "", "Week " & INT((DAY(I36)-1)/7)+1 & " of " & TEXT(I36, "mmmm")) -> Week 4 of December
A37: HealthSync Ltd | B37: 856 | C37: Probiotic Complex | D37: M1 | E37: 25°C/60%RH | F37: 46081 | G37: 46084 | H37: 46098 | I37: 46091 | J37: 46121 | K37: =IF(I37="","",I37-G37) -> 7 | L37: Active | M37: In Progress | P37: 26-04-012 | S37: =TRIM(CLEAN(B37))&"|"&TRIM(CLEAN(D37)) -> 856|M1 | T37: =IF(N37="","Pending",N37) -> Pending | U37: =IF(I37="","",YEAR(I37)) -> 2026 | V37: =IF(P37="N/A","No OOS",IF(ISNUMBER(FIND("OOS Closed",Q37)),"Closed","Open")) -> Open | W37: =IF(I37="", "", "Week " & INT((DAY(I37)-1)/7)+1 & " of " & TEXT(I37, "mmmm")) -> Week 2 of March
A38: HealthSync Ltd | B38: 875 | C38: Turmeric Extract Capsules | D38: M3 | E38: 30°C/65%RH | F38: 45801 | G38: 45808 | H38: 45822 | I38: 45815 | J38: 45845 | K38: =IF(I38="","",I38-G38) -> 7 | L38: Active | M38: In Progress | P38: N/A | S38: =TRIM(CLEAN(B38))&"|"&TRIM(CLEAN(D38)) -> 875|M3 | T38: =IF(N38="","Pending",N38) -> Pending | U38: =IF(I38="","",YEAR(I38)) -> 2025 | V38: =IF(P38="N/A","No OOS",IF(ISNUMBER(FIND("OOS Closed",Q38)),"Closed","Open")) -> No OOS | W38: =IF(I38="", "", "Week " & INT((DAY(I38)-1)/7)+1 & " of " & TEXT(I38, "mmmm")) -> Week 1 of June
A39: HealthSync Ltd | B39: 875 | C39: Turmeric Extract Capsules | D39: M12 | E39: 40°C/75%RH | F39: 46166 | G39: 46167 | H39: 46181 | I39: 46174 | J39: 46204 | K39: =IF(I39="","",I39-G39) -> 7 | L39: Active | M39: In Progress | O39: QIDR-206 | P39: N/A | S39: =TRIM(CLEAN(B39))&"|"&TRIM(CLEAN(D39)) -> 875|M12 | T39: =IF(N39="","Pending",N39) -> Pending | U39: =IF(I39="","",YEAR(I39)) -> 2026 | V39: =IF(P39="N/A","No OOS",IF(ISNUMBER(FIND("OOS Closed",Q39)),"Closed","Open")) -> No OOS | W39: =IF(I39="", "", "Week " & INT((DAY(I39)-1)/7)+1 & " of " & TEXT(I39, "mmmm")) -> Week 1 of June
A40: HealthSync Ltd | B40: 875 | C40: Turmeric Extract Capsules | D40: M36 | E40: 30°C/65%RH | F40: 45812 | G40: 45809 | H40: 45823 | I40: 45816 | J40: 45846 | K40: =IF(I40="","",I40-G40) -> 7 | L40: Active | M40: In Progress | N40: Completed | P40: N/A | R40: Yes | S40: =TRIM(CLEAN(B40))&"|"&TRIM(CLEAN(D40)) -> 875|M36 | T40: =IF(N40="","Pending",N40) -> Completed | U40: =IF(I40="","",YEAR(I40)) -> 2025 | V40: =IF(P40="N/A","No OOS",IF(ISNUMBER(FIND("OOS Closed",Q40)),"Closed","Open")) -> No OOS | W40: =IF(I40="", "", "Week " & INT((DAY(I40)-1)/7)+1 & " of " & TEXT(I40, "mmmm")) -> Week 2 of June
A41: HealthSync Ltd | B41: 882 | C41: Turmeric Extract Capsules | D41: M9 | E41: 25°C/60%RH | F41: 46181 | G41: 46174 | H41: 46188 | I41: 46181 | J41: 46211 | K41: =IF(I41="","",I41-G41) -> 7 | L41: Active | M41: In Progress | N41: Completed | P41: 26-03-007 | Q41: OOS Closed | R41: Yes | S41: =TRIM(CLEAN(B41))&"|"&TRIM(CLEAN(D41)) -> 882|M9 | T41: =IF(N41="","Pending",N41) -> Completed | U41: =IF(I41="","",YEAR(I41)) -> 2026 | V41: =IF(P41="N/A","No OOS",IF(ISNUMBER(FIND("OOS Closed",Q41)),"Closed","Open")) -> Closed | W41: =IF(I41="", "", "Week " & INT((DAY(I41)-1)/7)+1 & " of " & TEXT(I41, "mmmm")) -> Week 2 of June
...

Sheet INVOICE & REPORT TRACKER
A1: ℹ️ DEMO FILE — All data is fictitious for portfolio purposes only
A2: INVOICE & REPORT TRACKER — Demo Data
A3: Client | B3: Stability No. | C3: Product Name | D3: Batch No. | E3: Timepoint | F3: Invoice No. | G3: Report Sent Deadline | H3: Report Sent to Client Date | I3: PO | J3: Status Final | K3: KEY (Stability+Timepoint) | L3: Invoice Status
A4: NovaMed Pharma | B4: 801 | C4: Omega-3 Fish Oil Capsules | D4: BN-9864 | E4: M9 | F4: IN2600004 | G4: 45809 | H4: 45795 | I4: PO-90931 | J4: =IF(ISNUMBER(IFERROR(INDEX('WEEKLY PULL-OUT SCHEDULE'!$T:$T,MATCH(K4,'WEEKLY PULL-OUT SCHEDULE'!$S:$S,0)),"")),"",IFERROR(INDEX('WEEKLY PULL-OUT SCHEDULE'!$T:$T,MATCH(K4,'WEEKLY PULL-OUT SCHEDULE'!$S:$S,0)),"")) -> Completed | K4: =TRIM(CLEAN(B4))&"|"&TRIM(CLEAN(E4)) -> 801|M9 | L4: =IF(F4="","Pending","Issued") -> Issued
A5: NovaMed Pharma | B5: 801 | C5: Omega-3 Fish Oil Capsules | D5: BN-2480 | E5: M24 | F5: IN2600006 | I5: PO-66881 | J5: =IF(ISNUMBER(IFERROR(INDEX('WEEKLY PULL-OUT SCHEDULE'!$T:$T,MATCH(K5,'WEEKLY PULL-OUT SCHEDULE'!$S:$S,0)),"")),"",IFERROR(INDEX('WEEKLY PULL-OUT SCHEDULE'!$T:$T,MATCH(K5,'WEEKLY PULL-OUT SCHEDULE'!$S:$S,0)),"")) -> Pending | K5: =TRIM(CLEAN(B5))&"|"&TRIM(CLEAN(E5)) -> 801|M24 | L5: =IF(F5="","Pending","Issued") -> Issued
A6: NovaMed Pharma | B6: 801 | C6: Omega-3 Fish Oil Capsules | D6: BN-8269 | E6: M1 | G6: 45845 | J6: =IF(ISNUMBER(IFERROR(INDEX('WEEKLY PULL-OUT SCHEDULE'!$T:$T,MATCH(K6,'WEEKLY PULL-OUT SCHEDULE'!$S:$S,0)),"")),"",IFERROR(INDEX('WEEKLY PULL-OUT SCHEDULE'!$T:$T,MATCH(K6,'WEEKLY PULL-OUT SCHEDULE'!$S:$S,0)),"")) -> Pending | K6: =TRIM(CLEAN(B6))&"|"&TRIM(CLEAN(E6)) -> 801|M1 | L6: =IF(F6="","Pending","Issued") -> Pending
A7: NovaMed Pharma | B7: 801 | C7: Omega-3 Fish Oil Capsules | D7: BN-1753 | E7: M12 | G7: 46206 | J7: =IF(ISNUMBER(IFERROR(INDEX('WEEKLY PULL-OUT SCHEDULE'!$T:$T,MATCH(K7,'WEEKLY PULL-OUT SCHEDULE'!$S:$S,0)),"")),"",IFERROR(INDEX('WEEKLY PULL-OUT SCHEDULE'!$T:$T,MATCH(K7,'WEEKLY PULL-OUT SCHEDULE'!$S:$S,0)),"")) -> Pending | K7: =TRIM(CLEAN(B7))&"|"&TRIM(CLEAN(E7)) -> 801|M12 | L7: =IF(F7="","Pending","Issued") -> Pending
A8: NovaMed Pharma | B8: 821 | C8: Zinc Lozenges 10mg | D8: BN-7141 | E8: M9 | G8: 45833 | J8: =IF(ISNUMBER(IFERROR(INDEX('WEEKLY PULL-OUT SCHEDULE'!$T:$T,MATCH(K8,'WEEKLY PULL-OUT SCHEDULE'!$S:$S,0)),"")),"",IFERROR(INDEX('WEEKLY PULL-OUT SCHEDULE'!$T:$T,MATCH(K8,'WEEKLY PULL-OUT SCHEDULE'!$S:$S,0)),"")) -> Not Completed | K8: =TRIM(CLEAN(B8))&"|"&TRIM(CLEAN(E8)) -> 821|M9 | L8: =IF(F8="","Pending","Issued") -> Pending
A9: NovaMed Pharma | B9: 821 | C9: Zinc Lozenges 10mg | D9: BN-3950 | E9: M18 | G9: 45979 | J9: =IF(ISNUMBER(IFERROR(INDEX('WEEKLY PULL-OUT SCHEDULE'!$T:$T,MATCH(K9,'WEEKLY PULL-OUT SCHEDULE'!$S:$S,0)),"")),"",IFERROR(INDEX('WEEKLY PULL-OUT SCHEDULE'!$T:$T,MATCH(K9,'WEEKLY PULL-OUT SCHEDULE'!$S:$S,0)),"")) -> Pending | K9: =TRIM(CLEAN(B9))&"|"&TRIM(CLEAN(E9)) -> 821|M18 | L9: =IF(F9="","Pending","Issued") -> Pending
A10: NovaMed Pharma | B10: 821 | C10: Zinc Lozenges 10mg | D10: BN-4945 | E10: M1 | G10: 45829 | J10: =IF(ISNUMBER(IFERROR(INDEX('WEEKLY PULL-OUT SCHEDULE'!$T:$T,MATCH(K10,'WEEKLY PULL-OUT SCHEDULE'!$S:$S,0)),"")),"",IFERROR(INDEX('WEEKLY PULL-OUT SCHEDULE'!$T:$T,MATCH(K10,'WEEKLY PULL-OUT SCHEDULE'!$S:$S,0)),"")) -> Not Completed | K10: =TRIM(CLEAN(B10))&"|"&TRIM(CLEAN(E10)) -> 821|M1 | L10: =IF(F10="","Pending","Issued") -> Pending
A11: NovaMed Pharma | B11: 821 | C11: Zinc Lozenges 10mg | D11: BN-8555 | E11: M24 | G11: 46120 | J11: =IF(ISNUMBER(IFERROR(INDEX('WEEKLY PULL-OUT SCHEDULE'!$T:$T,MATCH(K11,'WEEKLY PULL-OUT SCHEDULE'!$S:$S,0)),"")),"",IFERROR(INDEX('WEEKLY PULL-OUT SCHEDULE'!$T:$T,MATCH(K11,'WEEKLY PULL-OUT SCHEDULE'!$S:$S,0)),"")) -> Pending | K11: =TRIM(CLEAN(B11))&"|"&TRIM(CLEAN(E11)) -> 821|M24 | L11: =IF(F11="","Pending","Issued") -> Pending
A12: NovaMed Pharma | B12: 821 | C12: Zinc Lozenges 10mg | D12: BN-8622 | E12: M3 | G12: 45910 | J12: =IF(ISNUMBER(IFERROR(INDEX('WEEKLY PULL-OUT SCHEDULE'!$T:$T,MATCH(K12,'WEEKLY PULL-OUT SCHEDULE'!$S:$S,0)),"")),"",IFERROR(INDEX('WEEKLY PULL-OUT SCHEDULE'!$T:$T,MATCH(K12,'WEEKLY PULL-OUT SCHEDULE'!$S:$S,0)),"")) -> Completed | K12: =TRIM(CLEAN(B12))&"|"&TRIM(CLEAN(E12)) -> 821|M3 | L12: =IF(F12="","Pending","Issued") -> Pending
A13: NovaMed Pharma | B13: 832 | C13: Turmeric Extract Capsules | D13: BN-2210 | E13: M36 | J13: =IF(ISNUMBER(IFERROR(INDEX('WEEKLY PULL-OUT SCHEDULE'!$T:$T,MATCH(K13,'WEEKLY PULL-OUT SCHEDULE'!$S:$S,0)),"")),"",IFERROR(INDEX('WEEKLY PULL-OUT SCHEDULE'!$T:$T,MATCH(K13,'WEEKLY PULL-OUT SCHEDULE'!$S:$S,0)),"")) -> Pending | K13: =TRIM(CLEAN(B13))&"|"&TRIM(CLEAN(E13)) -> 832|M36 | L13: =IF(F13="","Pending","Issued") -> Pending
A14: NovaMed Pharma | B14: 832 | C14: Turmeric Extract Capsules | D14: BN-5901 | E14: M9 | G14: 46091 | J14: =IF(ISNUMBER(IFERROR(INDEX('WEEKLY PULL-OUT SCHEDULE'!$T:$T,MATCH(K14,'WEEKLY PULL-OUT SCHEDULE'!$S:$S,0)),"")),"",IFERROR(INDEX('WEEKLY PULL-OUT SCHEDULE'!$T:$T,MATCH(K14,'WEEKLY PULL-OUT SCHEDULE'!$S:$S,0)),"")) -> Pending | K14: =TRIM(CLEAN(B14))&"|"&TRIM(CLEAN(E14)) -> 832|M9 | L14: =IF(F14="","Pending","Issued") -> Pending
A15: NovaMed Pharma | B15: 832 | C15: Turmeric Extract Capsules | D15: BN-8484 | E15: M18 | J15: =IF(ISNUMBER(IFERROR(INDEX('WEEKLY PULL-OUT SCHEDULE'!$T:$T,MATCH(K15,'WEEKLY PULL-OUT SCHEDULE'!$S:$S,0)),"")),"",IFERROR(INDEX('WEEKLY PULL-OUT SCHEDULE'!$T:$T,MATCH(K15,'WEEKLY PULL-OUT SCHEDULE'!$S:$S,0)),"")) -> Pending | K15: =TRIM(CLEAN(B15))&"|"&TRIM(CLEAN(E15)) -> 832|M18 | L15: =IF(F15="","Pending","Issued") -> Pending
A16: NovaMed Pharma | B16: 832 | C16: Turmeric Extract Capsules | D16: BN-8916 | E16: M24 | G16: 46009 | J16: =IF(ISNUMBER(IFERROR(INDEX('WEEKLY PULL-OUT SCHEDULE'!$T:$T,MATCH(K16,'WEEKLY PULL-OUT SCHEDULE'!$S:$S,0)),"")),"",IFERROR(INDEX('WEEKLY PULL-OUT SCHEDULE'!$T:$T,MATCH(K16,'WEEKLY PULL-OUT SCHEDULE'!$S:$S,0)),"")) -> Completed | K16: =TRIM(CLEAN(B16))&"|"&TRIM(CLEAN(E16)) -> 832|M24 | L16: =IF(F16="","Pending","Issued") -> Pending
A17: NovaMed Pharma | B17: 833 | C17: CoQ10 100mg Softgels | D17: BN-5847 | E17: M12 | G17: 45943 | J17: =IF(ISNUMBER(IFERROR(INDEX('WEEKLY PULL-OUT SCHEDULE'!$T:$T,MATCH(K17,'WEEKLY PULL-OUT SCHEDULE'!$S:$S,0)),"")),"",IFERROR(INDEX('WEEKLY PULL-OUT SCHEDULE'!$T:$T,MATCH(K17,'WEEKLY PULL-OUT SCHEDULE'!$S:$S,0)),"")) -> Not Completed | K17: =TRIM(CLEAN(B17))&"|"&TRIM(CLEAN(E17)) -> 833|M12 | L17: =IF(F17="","Pending","Issued") -> Pending
A18: NovaMed Pharma | B18: 833 | C18: CoQ10 100mg Softgels | D18: BN-5497 | E18: M24 | G18: 45847 | J18: =IF(ISNUMBER(IFERROR(INDEX('WEEKLY PULL-OUT SCHEDULE'!$T:$T,MATCH(K18,'WEEKLY PULL-OUT SCHEDULE'!$S:$S,0)),"")),"",IFERROR(INDEX('WEEKLY PULL-OUT SCHEDULE'!$T:$T,MATCH(K18,'WEEKLY PULL-OUT SCHEDULE'!$S:$S,0)),"")) -> Pending | K18: =TRIM(CLEAN(B18))&"|"&TRIM(CLEAN(E18)) -> 833|M24 | L18: =IF(F18="","Pending","Issued") -> Pending
A19: BioCore Labs | B19: 843 | C19: Iron Supplement Drops | D19: BN-9138 | E19: M1 | J19: =IF(ISNUMBER(IFERROR(INDEX('WEEKLY PULL-OUT SCHEDULE'!$T:$T,MATCH(K19,'WEEKLY PULL-OUT SCHEDULE'!$S:$S,0)),"")),"",IFERROR(INDEX('WEEKLY PULL-OUT SCHEDULE'!$T:$T,MATCH(K19,'WEEKLY PULL-OUT SCHEDULE'!$S:$S,0)),"")) -> Pending | K19: =TRIM(CLEAN(B19))&"|"&TRIM(CLEAN(E19)) -> 843|M1 | L19: =IF(F19="","Pending","Issued") -> Pending
A20: BioCore Labs | B20: 843 | C20: Iron Supplement Drops | D20: BN-6772 | E20: M3 | F20: IN2600046 | G20: 46074 | H20: 46066 | I20: PO-93442 | J20: =IF(ISNUMBER(IFERROR(INDEX('WEEKLY PULL-OUT SCHEDULE'!$T:$T,MATCH(K20,'WEEKLY PULL-OUT SCHEDULE'!$S:$S,0)),"")),"",IFERROR(INDEX('WEEKLY PULL-OUT SCHEDULE'!$T:$T,MATCH(K20,'WEEKLY PULL-OUT SCHEDULE'!$S:$S,0)),"")) -> Pending | K20: =TRIM(CLEAN(B20))&"|"&TRIM(CLEAN(E20)) -> 843|M3 | L20: =IF(F20="","Pending","Issued") -> Issued
A21: BioCore Labs | B21: 843 | C21: Iron Supplement Drops | D21: BN-2591 | E21: M12 | G21: 46136 | J21: =IF(ISNUMBER(IFERROR(INDEX('WEEKLY PULL-OUT SCHEDULE'!$T:$T,MATCH(K21,'WEEKLY PULL-OUT SCHEDULE'!$S:$S,0)),"")),"",IFERROR(INDEX('WEEKLY PULL-OUT SCHEDULE'!$T:$T,MATCH(K21,'WEEKLY PULL-OUT SCHEDULE'!$S:$S,0)),"")) -> Pending | K21: =TRIM(CLEAN(B21))&"|"&TRIM(CLEAN(E21)) -> 843|M12 | L21: =IF(F21="","Pending","Issued") -> Pending
A22: BioCore Labs | B22: 843 | C22: Iron Supplement Drops | D22: BN-8222 | E22: M36 | G22: 45966 | J22: =IF(ISNUMBER(IFERROR(INDEX('WEEKLY PULL-OUT SCHEDULE'!$T:$T,MATCH(K22,'WEEKLY PULL-OUT SCHEDULE'!$S:$S,0)),"")),"",IFERROR(INDEX('WEEKLY PULL-OUT SCHEDULE'!$T:$T,MATCH(K22,'WEEKLY PULL-OUT SCHEDULE'!$S:$S,0)),"")) -> Pending | K22: =TRIM(CLEAN(B22))&"|"&TRIM(CLEAN(E22)) -> 843|M36 | L22: =IF(F22="","Pending","Issued") -> Pending
A23: BioCore Labs | B23: 851 | C23: Vitamin C 500mg Tablets | D23: BN-6352 | E23: M24 | G23: 46244 | J23: =IF(ISNUMBER(IFERROR(INDEX('WEEKLY PULL-OUT SCHEDULE'!$T:$T,MATCH(K23,'WEEKLY PULL-OUT SCHEDULE'!$S:$S,0)),"")),"",IFERROR(INDEX('WEEKLY PULL-OUT SCHEDULE'!$T:$T,MATCH(K23,'WEEKLY PULL-OUT SCHEDULE'!$S:$S,0)),"")) -> Pending | K23: =TRIM(CLEAN(B23))&"|"&TRIM(CLEAN(E23)) -> 851|M24 | L23: =IF(F23="","Pending","Issued") -> Pending
A24: BioCore Labs | B24: 851 | C24: Vitamin C 500mg Tablets | D24: BN-9837 | E24: M6 | G24: 45842 | J24: =IF(ISNUMBER(IFERROR(INDEX('WEEKLY PULL-OUT SCHEDULE'!$T:$T,MATCH(K24,'WEEKLY PULL-OUT SCHEDULE'!$S:$S,0)),"")),"",IFERROR(INDEX('WEEKLY PULL-OUT SCHEDULE'!$T:$T,MATCH(K24,'WEEKLY PULL-OUT SCHEDULE'!$S:$S,0)),"")) -> Pending | K24: =TRIM(CLEAN(B24))&"|"&TRIM(CLEAN(E24)) -> 851|M6 | L24: =IF(F24="","Pending","Issued") -> Pending
A25: HealthSync Ltd | B25: 853 | C25: Omega-3 Fish Oil Capsules | D25: BN-5465 | E25: M18 | G25: 45864 | J25: =IF(ISNUMBER(IFERROR(INDEX('WEEKLY PULL-OUT SCHEDULE'!$T:$T,MATCH(K25,'WEEKLY PULL-OUT SCHEDULE'!$S:$S,0)),"")),"",IFERROR(INDEX('WEEKLY PULL-OUT SCHEDULE'!$T:$T,MATCH(K25,'WEEKLY PULL-OUT SCHEDULE'!$S:$S,0)),"")) -> Not Completed | K25: =TRIM(CLEAN(B25))&"|"&TRIM(CLEAN(E25)) -> 853|M18 | L25: =IF(F25="","Pending","Issued") -> Pending
A26: HealthSync Ltd | B26: 853 | C26: Omega-3 Fish Oil Capsules | D26: BN-5835 | E26: M24 | G26: 46074 | J26: =IF(ISNUMBER(IFERROR(INDEX('WEEKLY PULL-OUT SCHEDULE'!$T:$T,MATCH(K26,'WEEKLY PULL-OUT SCHEDULE'!$S:$S,0)),"")),"",IFERROR(INDEX('WEEKLY PULL-OUT SCHEDULE'!$T:$T,MATCH(K26,'WEEKLY PULL-OUT SCHEDULE'!$S:$S,0)),"")) -> Completed | K26: =TRIM(CLEAN(B26))&"|"&TRIM(CLEAN(E26)) -> 853|M24 | L26: =IF(F26="","Pending","Issued") -> Pending
A27: HealthSync Ltd | B27: 853 | C27: Omega-3 Fish Oil Capsules | D27: BN-8673 | E27: M1 | G27: 46001 | J27: =IF(ISNUMBER(IFERROR(INDEX('WEEKLY PULL-OUT SCHEDULE'!$T:$T,MATCH(K27,'WEEKLY PULL-OUT SCHEDULE'!$S:$S,0)),"")),"",IFERROR(INDEX('WEEKLY PULL-OUT SCHEDULE'!$T:$T,MATCH(K27,'WEEKLY PULL-OUT SCHEDULE'!$S:$S,0)),"")) -> Pending | K27: =TRIM(CLEAN(B27))&"|"&TRIM(CLEAN(E27)) -> 853|M1 | L27: =IF(F27="","Pending","Issued") -> Pending
A28: HealthSync Ltd | B28: 853 | C28: Omega-3 Fish Oil Capsules | D28: BN-7511 | E28: M3 | G28: 45992 | J28: =IF(ISNUMBER(IFERROR(INDEX('WEEKLY PULL-OUT SCHEDULE'!$T:$T,MATCH(K28,'WEEKLY PULL-OUT SCHEDULE'!$S:$S,0)),"")),"",IFERROR(INDEX('WEEKLY PULL-OUT SCHEDULE'!$T:$T,MATCH(K28,'WEEKLY PULL-OUT SCHEDULE'!$S:$S,0)),"")) -> Pending | K28: =TRIM(CLEAN(B28))&"|"&TRIM(CLEAN(E28)) -> 853|M3 | L28: =IF(F28="","Pending","Issued") -> Pending
A29: HealthSync Ltd | B29: 853 | C29: Omega-3 Fish Oil Capsules | D29: BN-2479 | E29: M12 | G29: 45822 | J29: =IF(ISNUMBER(IFERROR(INDEX('WEEKLY PULL-OUT SCHEDULE'!$T:$T,MATCH(K29,'WEEKLY PULL-OUT SCHEDULE'!$S:$S,0)),"")),"",IFERROR(INDEX('WEEKLY PULL-OUT SCHEDULE'!$T:$T,MATCH(K29,'WEEKLY PULL-OUT SCHEDULE'!$S:$S,0)),"")) -> Pending | K29: =TRIM(CLEAN(B29))&"|"&TRIM(CLEAN(E29)) -> 853|M12 | L29: =IF(F29="","Pending","Issued") -> Pending
A30: HealthSync Ltd | B30: 853 | C30: Omega-3 Fish Oil Capsules | D30: BN-3024 | E30: M36 | G30: 46050 | J30: =IF(ISNUMBER(IFERROR(INDEX('WEEKLY PULL-OUT SCHEDULE'!$T:$T,MATCH(K30,'WEEKLY PULL-OUT SCHEDULE'!$S:$S,0)),"")),"",IFERROR(INDEX('WEEKLY PULL-OUT SCHEDULE'!$T:$T,MATCH(K30,'WEEKLY PULL-OUT SCHEDULE'!$S:$S,0)),"")) -> Pending | K30: =TRIM(CLEAN(B30))&"|"&TRIM(CLEAN(E30)) -> 853|M36 | L30: =IF(F30="","Pending","Issued") -> Pending
A31: HealthSync Ltd | B31: 856 | C31: Probiotic Complex | D31: BN-7242 | E31: M9 | G31: 46084 | J31: =IF(ISNUMBER(IFERROR(INDEX('WEEKLY PULL-OUT SCHEDULE'!$T:$T,MATCH(K31,'WEEKLY PULL-OUT SCHEDULE'!$S:$S,0)),"")),"",IFERROR(INDEX('WEEKLY PULL-OUT SCHEDULE'!$T:$T,MATCH(K31,'WEEKLY PULL-OUT SCHEDULE'!$S:$S,0)),"")) -> Pending | K31: =TRIM(CLEAN(B31))&"|"&TRIM(CLEAN(E31)) -> 856|M9 | L31: =IF(F31="","Pending","Issued") -> Pending
A32: HealthSync Ltd | B32: 856 | C32: Probiotic Complex | D32: BN-4830 | E32: M36 | F32: IN2600080 | G32: 46060 | H32: 46060 | I32: PO-13280 | J32: =IF(ISNUMBER(IFERROR(INDEX('WEEKLY PULL-OUT SCHEDULE'!$T:$T,MATCH(K32,'WEEKLY PULL-OUT SCHEDULE'!$S:$S,0)),"")),"",IFERROR(INDEX('WEEKLY PULL-OUT SCHEDULE'!$T:$T,MATCH(K32,'WEEKLY PULL-OUT SCHEDULE'!$S:$S,0)),"")) -> Pending | K32: =TRIM(CLEAN(B32))&"|"&TRIM(CLEAN(E32)) -> 856|M36 | L32: =IF(F32="","Pending","Issued") -> Issued
A33: HealthSync Ltd | B33: 856 | C33: Probiotic Complex | D33: BN-4626 | E33: M1 | F33: IN2600083 | G33: 46136 | H33: 46141 | I33: PO-18285 | J33: =IF(ISNUMBER(IFERROR(INDEX('WEEKLY PULL-OUT SCHEDULE'!$T:$T,MATCH(K33,'WEEKLY PULL-OUT SCHEDULE'!$S:$S,0)),"")),"",IFERROR(INDEX('WEEKLY PULL-OUT SCHEDULE'!$T:$T,MATCH(K33,'WEEKLY PULL-OUT SCHEDULE'!$S:$S,0)),"")) -> Pending | K33: =TRIM(CLEAN(B33))&"|"&TRIM(CLEAN(E33)) -> 856|M1 | L33: =IF(F33="","Pending","Issued") -> Issued
A34: HealthSync Ltd | B34: 875 | C34: Turmeric Extract Capsules | D34: BN-7689 | E34: M3 | G34: 45860 | J34: =IF(ISNUMBER(IFERROR(INDEX('WEEKLY PULL-OUT SCHEDULE'!$T:$T,MATCH(K34,'WEEKLY PULL-OUT SCHEDULE'!$S:$S,0)),"")),"",IFERROR(INDEX('WEEKLY PULL-OUT SCHEDULE'!$T:$T,MATCH(K34,'WEEKLY PULL-OUT SCHEDULE'!$S:$S,0)),"")) -> Pending | K34: =TRIM(CLEAN(B34))&"|"&TRIM(CLEAN(E34)) -> 875|M3 | L34: =IF(F34="","Pending","Issued") -> Pending
A35: HealthSync Ltd | B35: 875 | C35: Turmeric Extract Capsules | D35: BN-5986 | E35: M12 | G35: 46219 | J35: =IF(ISNUMBER(IFERROR(INDEX('WEEKLY PULL-OUT SCHEDULE'!$T:$T,MATCH(K35,'WEEKLY PULL-OUT SCHEDULE'!$S:$S,0)),"")),"",IFERROR(INDEX('WEEKLY PULL-OUT SCHEDULE'!$T:$T,MATCH(K35,'WEEKLY PULL-OUT SCHEDULE'!$S:$S,0)),"")) -> Pending | K35: =TRIM(CLEAN(B35))&"|"&TRIM(CLEAN(E35)) -> 875|M12 | L35: =IF(F35="","Pending","Issued") -> Pending
A36: HealthSync Ltd | B36: 875 | C36: Turmeric Extract Capsules | D36: BN-9807 | E36: M36 | G36: 45861 | J36: =IF(ISNUMBER(IFERROR(INDEX('WEEKLY PULL-OUT SCHEDULE'!$T:$T,MATCH(K36,'WEEKLY PULL-OUT SCHEDULE'!$S:$S,0)),"")),"",IFERROR(INDEX('WEEKLY PULL-OUT SCHEDULE'!$T:$T,MATCH(K36,'WEEKLY PULL-OUT SCHEDULE'!$S:$S,0)),"")) -> Completed | K36: =TRIM(CLEAN(B36))&"|"&TRIM(CLEAN(E36)) -> 875|M36 | L36: =IF(F36="","Pending","Issued") -> Pending
A37: HealthSync Ltd | B37: 882 | C37: Turmeric Extract Capsules | D37: BN-7866 | E37: M9 | G37: 46226 | J37: =IF(ISNUMBER(IFERROR(INDEX('WEEKLY PULL-OUT SCHEDULE'!$T:$T,MATCH(K37,'WEEKLY PULL-OUT SCHEDULE'!$S:$S,0)),"")),"",IFERROR(INDEX('WEEKLY PULL-OUT SCHEDULE'!$T:$T,MATCH(K37,'WEEKLY PULL-OUT SCHEDULE'!$S:$S,0)),"")) -> Completed | K37: =TRIM(CLEAN(B37))&"|"&TRIM(CLEAN(E37)) -> 882|M9 | L37: =IF(F37="","Pending","Issued") -> Pending
A38: HealthSync Ltd | B38: 882 | C38: Turmeric Extract Capsules | D38: BN-2622 | E38: M18 | G38: 46119 | J38: =IF(ISNUMBER(IFERROR(INDEX('WEEKLY PULL-OUT SCHEDULE'!$T:$T,MATCH(K38,'WEEKLY PULL-OUT SCHEDULE'!$S:$S,0)),"")),"",IFERROR(INDEX('WEEKLY PULL-OUT SCHEDULE'!$T:$T,MATCH(K38,'WEEKLY PULL-OUT SCHEDULE'!$S:$S,0)),"")) -> Not Completed | K38: =TRIM(CLEAN(B38))&"|"&TRIM(CLEAN(E38)) -> 882|M18 | L38: =IF(F38="","Pending","Issued") -> Pending
A39: HealthSync Ltd | B39: 882 | C39: Turmeric Extract Capsules | D39: BN-1536 | E39: M24 | J39: =IF(ISNUMBER(IFERROR(INDEX('WEEKLY PULL-OUT SCHEDULE'!$T:$T,MATCH(K39,'WEEKLY PULL-OUT SCHEDULE'!$S:$S,0)),"")),"",IFERROR(INDEX('WEEKLY PULL-OUT SCHEDULE'!$T:$T,MATCH(K39,'WEEKLY PULL-OUT SCHEDULE'!$S:$S,0)),"")) -> Pending | K39: =TRIM(CLEAN(B39))&"|"&TRIM(CLEAN(E39)) -> 882|M24 | L39: =IF(F39="","Pending","Issued") -> Pending
A40: HealthSync Ltd | B40: 882 | C40: Turmeric Extract Capsules | D40: BN-4868 | E40: M6 | J40: =IF(ISNUMBER(IFERROR(INDEX('WEEKLY PULL-OUT SCHEDULE'!$T:$T,MATCH(K40,'WEEKLY PULL-OUT SCHEDULE'!$S:$S,0)),"")),"",IFERROR(INDEX('WEEKLY PULL-OUT SCHEDULE'!$T:$T,MATCH(K40,'WEEKLY PULL-OUT SCHEDULE'!$S:$S,0)),"")) -> Pending | K40: =TRIM(CLEAN(B40))&"|"&TRIM(CLEAN(E40)) -> 882|M6 | L40: =IF(F40="","Pending","Issued") -> Pending
...

Sheet DASHBOARD
B2: Year | C2: (Todas)
B4: Cuenta de Status Final | C4: Etiquetas de columna
B5: Etiquetas de fila | C5: Completed | D5: Not Completed | E5: (en blanco) | F5: Total general
B6: AlphaChem Pty Ltd | C6: 2 | D6: 2 | F6: 4
B7: BioCore Labs
B8: ClearDose Corp | C8: 3 | D8: 1 | F8: 4
B9: HealthSync Ltd | C9: 3 | D9: 2 | F9: 5
B10: MediPro Australia | C10: 2 | D10: 3 | F10: 5
B11: NovaMed Pharma | C11: 3 | D11: 3 | F11: 6
B12: PurePath Wellness | C12: 2 | D12: 4 | F12: 6
B13: VitaShield Inc | D13: 3 | F13: 3
B14: Total general | C14: 15 | D14: 18 | F14: 33
B22: Year | C22: (Todas)
B24: Cuenta de OOS (Clean) | C24: Etiquetas de columna
B25: Etiquetas de fila | C25: Closed | D25: No OOS | E25: Open | F25: Total general
B26: AlphaChem Pty Ltd | C26: 7 | D26: 5 | F26: 12
B27: BioCore Labs | C27: 3 | D27: 2 | E27: 2 | F27: 7
B28: ClearDose Corp | C28: 5 | D28: 8 | E28: 4 | F28: 17
B29: HealthSync Ltd | C29: 2 | D29: 12 | E29: 3 | F29: 17
B30: MediPro Australia | C30: 5 | D30: 11 | E30: 4 | F30: 20
B31: NovaMed Pharma | D31: 11 | E31: 6 | F31: 17
B32: PurePath Wellness | C32: 2 | D32: 5 | E32: 5 | F32: 12
B33: VitaShield Inc | C33: 1 | D33: 3 | E33: 4 | F33: 8
B34: Total general | C34: 25 | D34: 57 | E34: 28 | F34: 110
B43: Cuenta de Invoice Status | C43: Etiquetas de columna
B44: Etiquetas de fila | C44: Issued | D44: Pending | E44: Total general
B45: AlphaChem Pty Ltd | C45: 1 | D45: 9 | E45: 10
B46: BioCore Labs | C46: 1 | D46: 5 | E46: 6
B47: ClearDose Corp | C47: 2 | D47: 13 | E47: 15
B48: HealthSync Ltd | C48: 2 | D48: 15 | E48: 17
B49: MediPro Australia | D49: 20 | E49: 20
B50: NovaMed Pharma | C50: 2 | D50: 13 | E50: 15
B51: PurePath Wellness | C51: 2 | D51: 8 | E51: 10
B52: VitaShield Inc | C52: 1 | D52: 7 | E52: 8
B53: Total general | C53: 11 | D53: 90 | E53: 101
B62: Year | C62: (Todas) | J62: Week (Actual Pull) | K62: (Todas)
B64: Cuenta de OOS (Clean) | C64: Etiquetas de columna | J64: Cuenta de Status Final (Clean) | K64: Etiquetas de columna
B65: Etiquetas de fila | C65: Closed | D65: No OOS | E65: Open | F65: Total general | J65: Etiquetas de fila | K65: Completed | L65: Not Completed | M65: Pending | N65: Total general
C66: 2 | D66: 11 | E66: 4 | F66: 17 | J66: AlphaChem Pty Ltd | K66: 2 | L66: 2 | M66: 8 | N66: 12
B67: Week 3 of April | C67: 2 | D67: 1 | E67: 1 | F67: 4 | J67: BioCore Labs | M67: 7 | N67: 7
...
